Workbook
Name Z_1E7B5665_E06C_D74F_B5BD_017FFD6F236B_.wvu.Cols: 'Nom du personnage'!$AF:$AG

Sheet Nom du personnage
C1: Informations du Joueur
C2: Prénon et nom:
C3: Date de naissance: | S3: Date du premier Arkadia:
C4: Numéro d'assurance maladie: | T4: TEL: | AP4: 0
C5: Numéro de téléphone en cas d'urgence:
C6: - | N6: Contact (Lien):
C7: - | N7: Contact (Lien):
C9: Allergies:
C14: Liste d'événements
M15: XPs | Q15: Événement | X15: Saison | AA15: XPs
C16: Création du personnage | M16: =VLOOKUP(F51,Données!C3:D32,2,FALSE) -> #N/A | AA16: =IF(ISERROR(VLOOKUP(Q16,Données!$A$3:$B$12,2,FALSE)),,VLOOKUP(Q16,Données!$A$3:$B$12,2,FALSE)) -> 0
AA17: =IF(ISERROR(VLOOKUP(Q17,Données!$A$3:$B$12,2,FALSE)),,VLOOKUP(Q17,Données!$A$3:$B$12,2,FALSE)) -> 0
AA18: =IF(ISERROR(VLOOKUP(Q18,Données!$A$3:$B$12,2,FALSE)),,VLOOKUP(Q18,Données!$A$3:$B$12,2,FALSE)) -> 0
M19: =SUM(M16:O18) -> #N/A | AA19: =IF(ISERROR(VLOOKUP(Q19,Données!$A$3:$B$12,2,FALSE)),,VLOOKUP(Q19,Données!$A$3:$B$12,2,FALSE)) -> 0
AA20: =IF(ISERROR(VLOOKUP(Q20,Données!$A$3:$B$12,2,FALSE)),,VLOOKUP(Q20,Données!$A$3:$B$12,2,FALSE)) -> 0
C21: Événement | J21: Saison | M21: XPs | AA21: =IF(ISERROR(VLOOKUP(Q21,Données!$A$3:$B$12,2,FALSE)),,VLOOKUP(Q21,Données!$A$3:$B$12,2,FALSE)) -> 0
M22: =IF(ISERROR(VLOOKUP(C22,Données!$A$3:$B$12,2,FALSE)),,VLOOKUP(C22,Données!$A$3:$B$12,2,FALSE)) -> 0 | AA22: =IF(ISERROR(VLOOKUP(Q22,Données!$A$3:$B$12,2,FALSE)),,VLOOKUP(Q22,Données!$A$3:$B$12,2,FALSE)) -> 0
M23: =IF(ISERROR(VLOOKUP(C23,Données!$A$3:$B$12,2,FALSE)),,VLOOKUP(C23,Données!$A$3:$B$12,2,FALSE)) -> 0 | AA23: =IF(ISERROR(VLOOKUP(Q23,Données!$A$3:$B$12,2,FALSE)),,VLOOKUP(Q23,Données!$A$3:$B$12,2,FALSE)) -> 0
M24: =IF(ISERROR(VLOOKUP(C24,Données!$A$3:$B$12,2,FALSE)),,VLOOKUP(C24,Données!$A$3:$B$12,2,FALSE)) -> 0 | AA24: =IF(ISERROR(VLOOKUP(Q24,Données!$A$3:$B$12,2,FALSE)),,VLOOKUP(Q24,Données!$A$3:$B$12,2,FALSE)) -> 0
M25: =IF(ISERROR(VLOOKUP(C25,Données!$A$3:$B$12,2,FALSE)),,VLOOKUP(C25,Données!$A$3:$B$12,2,FALSE)) -> 0 | AA25: =IF(ISERROR(VLOOKUP(Q25,Données!$A$3:$B$12,2,FALSE)),,VLOOKUP(Q25,Données!$A$3:$B$12,2,FALSE)) -> 0
M26: =IF(ISERROR(VLOOKUP(C26,Données!$A$3:$B$12,2,FALSE)),,VLOOKUP(C26,Données!$A$3:$B$12,2,FALSE)) -> 0 | AA26: =IF(ISERROR(VLOOKUP(Q26,Données!$A$3:$B$12,2,FALSE)),,VLOOKUP(Q26,Données!$A$3:$B$12,2,FALSE)) -> 0
M27: =IF(ISERROR(VLOOKUP(C27,Données!$A$3:$B$12,2,FALSE)),,VLOOKUP(C27,Données!$A$3:$B$12,2,FALSE)) -> 0 | AA27: =IF(ISERROR(VLOOKUP(Q27,Données!$A$3:$B$12,2,FALSE)),,VLOOKUP(Q27,Données!$A$3:$B$12,2,FALSE)) -> 0
M28: =IF(ISERROR(VLOOKUP(C28,Données!$A$3:$B$12,2,FALSE)),,VLOOKUP(C28,Données!$A$3:$B$12,2,FALSE)) -> 0 | AA28: =IF(ISERROR(VLOOKUP(Q28,Données!$A$3:$B$12,2,FALSE)),,VLOOKUP(Q28,Données!$A$3:$B$12,2,FALSE)) -> 0
M29: =IF(ISERROR(VLOOKUP(C29,Données!$A$3:$B$12,2,FALSE)),,VLOOKUP(C29,Données!$A$3:$B$12,2,FALSE)) -> 0 | AA29: =IF(ISERROR(VLOOKUP(Q29,Données!$A$3:$B$12,2,FALSE)),,VLOOKUP(Q29,Données!$A$3:$B$12,2,FALSE)) -> 0
M30: =IF(ISERROR(VLOOKUP(C30,Données!$A$3:$B$12,2,FALSE)),,VLOOKUP(C30,Données!$A$3:$B$12,2,FALSE)) -> 0 | AA30: =IF(ISERROR(VLOOKUP(Q30,Données!$A$3:$B$12,2,FALSE)),,VLOOKUP(Q30,Données!$A$3:$B$12,2,FALSE)) -> 0
M31: =IF(ISERROR(VLOOKUP(C31,Données!$A$3:$B$12,2,FALSE)),,VLOOKUP(C31,Données!$A$3:$B$12,2,FALSE)) -> 0 | AA31: =IF(ISERROR(VLOOKUP(Q31,Données!$A$3:$B$12,2,FALSE)),,VLOOKUP(Q31,Données!$A$3:$B$12,2,FALSE)) -> 0
M32: =IF(ISERROR(VLOOKUP(C32,Données!$A$3:$B$12,2,FALSE)),,VLOOKUP(C32,Données!$A$3:$B$12,2,FALSE)) -> 0 | AA32: =IF(ISERROR(VLOOKUP(Q32,Données!$A$3:$B$12,2,FALSE)),,VLOOKUP(Q32,Données!$A$3:$B$12,2,FALSE)) -> 0
M33: =IF(ISERROR(VLOOKUP(C33,Données!$A$3:$B$12,2,FALSE)),,VLOOKUP(C33,Données!$A$3:$B$12,2,FALSE)) -> 0 | AA33: =IF(ISERROR(VLOOKUP(Q33,Données!$A$3:$B$12,2,FALSE)),,VLOOKUP(Q33,Données!$A$3:$B$12,2,FALSE)) -> 0
... M42: =IF(ISERROR(VLOOKUP(C42,Données!$A$3:$B$12,2,FALSE)),,VLOOKUP(C42,Données!$A$3:$B$12,2,FALSE)) -> 0 | AA42: =IF(ISERROR(VLOOKUP(Q42,Données!$A$3:$B$12,2,FALSE)),,VLOOKUP(Q42,Données!$A$3:$B$12,2,FALSE)) -> 0
U44: Totals des XPs: | AA44: =MIN(150+M19,SUM(M22:O42)+M19+SUM(AA16:AC42)) -> #N/A
C47: Fiche du personnage
C48: Nom du personnage:
C49: Chances (restantes): | H49: 3 | O49: Date du premier évènement du personnage: | AA49: =+_xlfn.CONCAT(C22, ,J22)
C51: Race: | Q51: Carrière:
C52: Faiblesses: | F52: =Faiblesses!AB3 -> #N/A | Q52: Immunités: | U52: =Immunités!T2
C54: Religion:
C56: Maison Noble / Titre: | T56: Noblesse: | W56: Oui | Y56: =IF(COUNTIF(C66:AC85,"Noblesse"),"X",) -> 0 | AA56: Non | AC56: =IF(Y56="X",,"X") -> X
C58: Nombre de Points de Vie (PV): | J58: =VLOOKUP(F51,Données!C3:F32,3,FALSE)+COUNTIF(C66:AC85,Compétences!M18)+COUNTIF(C66:AC85,Compétences!B11)+COUNTIF(C66:AC85,Compétences!H808)-COUNTIF(C66:AC85,Compétences!B65) -> #N/A | K58: J | L58: =+VLOOKUP(F51,Données!C3:F32,4,FALSE)+COUNTIF(C66:AC85,Compétences!M18)+COUNTIF(C66:AC85,Compétences!B11)+COUNTIF(C66:AC85,Compétences!H808)-COUNTIF(C66:AC85,Compétences!B65) -> #N/A | M58: N | X58: Points de Magie: | AC58: =VLOOKUP(U51,Données!P3:Q30,2,FALSE)+(COUNTIF(C66:AC85,Compétences!B55)*3)+(COUNTIF(C66:AC85,Compétences!B50)*5) -> #N/A
M59: Type d'armure : | Q59: =VLOOKUP(U51,Données!H3:J30,3,FALSE) -> #N/A | X59: Niv. Max des sorts: | AC59: =MIN(VLOOKUP(U51,Données!P3:S30,4,FALSE)+(COUNTIF(C66:AC85,Compétences!B54)),10) -> #N/A
D60: Moralité: | M60: Points d'armure maximum : | S60: =MIN(10-J58,IF(COUNTIF(C66:AC85,"Mulet de bataille"),VLOOKUP(U51,Données!H3:I30,2,FALSE)+1,VLOOKUP(U51,Données!H3:I30,2,FALSE))) -> #N/A | T60: J | U60: =MIN(10-L58,IF(COUNTIF(C66:AC85,"Mulet de bataille"),VLOOKUP(U51,Données!H3:I30,2,FALSE)+1,VLOOKUP(U51,Données!H3:I30,2,FALSE))) -> #N/A | V60: N
...

Sheet Restriction de divinité
A1: Divinitées | C1: Races | E1: Moralité | G1: Race | H1: Divinité | I1: Moralité permises
A2: Arawn | C2: Demi-Elfe | E2: Bénéfique | G2: =C6 -> Elfe Sanguinaire | H2: =A33 -> Essence Infernale | I2: ='Nom du personnage'!$F$60=$E$4 -> FALSE | K2: {=IF(AND(OR($G$2:$G$17='Nom du personnage'!$F$51),'Restriction de divinité'!I2=TRUE),'Restriction de divinité'!H2,0)} -> 0
A3: Argonas | C3: Elfe Gris | E3: Balancée | G3: Norde | H3: Magni | I3: =OR('Nom du personnage'!$F$60='Restriction de divinité'!$E$3,'Nom du personnage'!$F$60='Restriction de divinité'!$E$2) -> FALSE | K3: {=IF(AND(OR($G$2:$G$17='Nom du personnage'!$F$51),'Restriction de divinité'!I3=TRUE),'Restriction de divinité'!H3,0)} -> 0
A4: Asmodérus | C4: Elfe Lunaire | E4: Maléfique | G4: Norde | H4: Vidar | I4: =TRUE -> TRUE | K4: {=IF(AND(OR($G$2:$G$17='Nom du personnage'!$F$51),'Restriction de divinité'!I4=TRUE),'Restriction de divinité'!H4,0)} -> 0
A5: Atem'ra | C5: Elfe Noir | G5: Norde | H5: Esprits de la guerre (Ulrick Silverwolf) | I5: ='Nom du personnage'!$F$60=$E$2 -> FALSE | K5: {=IF(AND(OR($G$2:$G$17='Nom du personnage'!$F$51),'Restriction de divinité'!I5=TRUE),'Restriction de divinité'!H5,0)} -> 0
A6: Cyrder | C6: Elfe Sanguinaire | G6: Norde | H6: Esprits de la guerre (Odann) | I6: ='Nom du personnage'!$F$60=$E$3 -> FALSE | K6: {=IF(AND(OR($G$2:$G$17='Nom du personnage'!$F$51),'Restriction de divinité'!I6=TRUE),'Restriction de divinité'!H6,0)} -> 0
A7: Elûna | C7: Elfe Sauvage | G7: Norde | H7: Esprits de la guerre (Khurn) | I7: ='Nom du personnage'!$F$60=$E$4 -> FALSE | K7: {=IF(AND(OR($G$2:$G$17='Nom du personnage'!$F$51),'Restriction de divinité'!I7=TRUE),'Restriction de divinité'!H7,0)} -> 0
A8: Leviastis | C8: Être Sylvestre (Terre) | G8: Norde | H8: Esprits de la nature | I8: =TRUE -> TRUE | K8: {=IF(AND(OR($G$2:$G$17='Nom du personnage'!$F$51),'Restriction de divinité'!I8=TRUE),'Restriction de divinité'!H8,0)} -> 0
A9: Lumer | C9: Être Sylvestre (Eau) | G9: Norde | H9: Esprits des morts | I9: =TRUE -> TRUE | K9: {=IF(AND(OR($G$2:$G$17='Nom du personnage'!$F$51),'Restriction de divinité'!I9=TRUE),'Restriction de divinité'!H9,0)} -> 0
A10: Magystia | C10: Être Sylvestre (Feu) | G10: Norde | H10: Esprit de l'Aube | I10: =OR('Nom du personnage'!$F$60='Restriction de divinité'!$E$3,'Nom du personnage'!$F$60='Restriction de divinité'!$E$2) -> FALSE | K10: {=IF(AND(OR($G$2:$G$17='Nom du personnage'!$F$51),'Restriction de divinité'!I10=TRUE),'Restriction de divinité'!H10,0)} -> 0
A11: Maskorino | C11: Être Sylvestre (Air) | G11: Norde | H11: Esprit de la Nuit | I11: ='Nom du personnage'!$F$60=$E$4 -> FALSE | K11: {=IF(AND(OR($G$2:$G$17='Nom du personnage'!$F$51),'Restriction de divinité'!I11=TRUE),'Restriction de divinité'!H11,0)} -> 0
A12: Myrkar | C12: Haut-Elfe | G12: Ratfolk | H12: Vermilord | I12: =OR('Nom du personnage'!$F$60='Restriction de divinité'!$E$3,'Nom du personnage'!$F$60='Restriction de divinité'!$E$4) -> FALSE | K12: {=IF(AND(OR($G$2:$G$17='Nom du personnage'!$F$51),'Restriction de divinité'!I12=TRUE),'Restriction de divinité'!H12,0)} -> 0
A13: Thurdek | C13: Humain | G13: Ratfolk | H13: Amida | I13: =OR('Nom du personnage'!$F$60='Restriction de divinité'!$E$3,'Nom du personnage'!$F$60='Restriction de divinité'!$E$2) -> FALSE | K13: {=IF(AND(OR($G$2:$G$17='Nom du personnage'!$F$51),'Restriction de divinité'!I13=TRUE),'Restriction de divinité'!H13,0)} -> 0
A14: Vermilord | C14: Nain | G14: Ratfolk | H14: Baku | I14: =OR('Nom du personnage'!$F$60='Restriction de divinité'!$E$3,'Nom du personnage'!$F$60='Restriction de divinité'!$E$2) -> FALSE | K14: {=IF(AND(OR($G$2:$G$17='Nom du personnage'!$F$51),'Restriction de divinité'!I14=TRUE),'Restriction de divinité'!H14,0)} -> 0
A15: Vorn | C15: Gobelin | G15: Ratfolk | H15: Izanagi & Izanami | I15: =OR('Nom du personnage'!$F$60='Restriction de divinité'!$E$4,'Nom du personnage'!$F$60='Restriction de divinité'!$E$2) -> FALSE | K15: {=IF(AND(OR($G$2:$G$17='Nom du personnage'!$F$51),'Restriction de divinité'!I15=TRUE),'Restriction de divinité'!H15,0)} -> 0
A16: Walërya | C16: Orque | G16: Ratfolk | H16: O-Kuni-Nushi | I16: =TRUE -> TRUE | K16: {=IF(AND(OR($G$2:$G$17='Nom du personnage'!$F$51),'Restriction de divinité'!I16=TRUE),'Restriction de divinité'!H16,0)} -> 0
A17: Amida | C17: Demi-Démon | G17: Ratfolk | H17: Esprits de la nature | I17: =TRUE -> TRUE | K17: {=IF(AND(OR($G$2:$G$17='Nom du personnage'!$F$51),'Restriction de divinité'!I17=TRUE),'Restriction de divinité'!H17,0)} -> 0
A18: Baku | C18: Illithyd
A19: Izanagi & Izanami | C19: Norde | G19: TRUE | H19: Arawn | I19: =OR('Nom du personnage'!$F$60='Restriction de divinité'!$E$2,'Nom du personnage'!$F$60='Restriction de divinité'!$E$4) -> FALSE | K19: {=IF(AND(OR($G$2:$G$17='Nom du personnage'!$F$51)=FALSE,'Restriction de divinité'!G19=TRUE,'Restriction de divinité'!I19=TRUE),'Restriction de divinité'!H19,0)} -> 0
A20: O-Kuni-Nushi | C20: Presqu'Humain | G20: TRUE | H20: Argonas | I20: =TRUE -> TRUE | K20: {=IF(AND(OR($G$2:$G$17='Nom du personnage'!$F$51)=FALSE,'Restriction de divinité'!G20=TRUE,'Restriction de divinité'!I20=TRUE),'Restriction de divinité'!H20,0)} -> Argonas
A21: Baldur | C21: Bossu | G21: TRUE | H21: Asmodérus | I21: =OR('Nom du personnage'!$F$60='Restriction de divinité'!$E$3,'Nom du personnage'!$F$60='Restriction de divinité'!$E$4) -> FALSE | K21: {=IF(AND(OR($G$2:$G$17='Nom du personnage'!$F$51)=FALSE,'Restriction de divinité'!G21=TRUE,'Restriction de divinité'!I21=TRUE),'Restriction de divinité'!H21,0)} -> 0
A22: Eir | C22: Gitan | G22: {=OR(C2='Nom du personnage'!$F$51,C16:C17='Nom du personnage'!$F$51,C5='Nom du personnage'!$F$51)} -> FALSE | H22: Atem'ra | I22: ='Nom du personnage'!$F$60=$E$4 -> FALSE | K22: {=IF(AND(OR($G$2:$G$17='Nom du personnage'!$F$51)=FALSE,'Restriction de divinité'!G22=TRUE,'Restriction de divinité'!I22=TRUE),'Restriction de divinité'!H22,0)} -> 0
A23: Honir | C23: Arboréen | G23: TRUE | H23: Cyrder | I23: ='Nom du personnage'!$F$60=$E$3 -> FALSE | K23: {=IF(AND(OR($G$2:$G$17='Nom du personnage'!$F$51)=FALSE,'Restriction de divinité'!G23=TRUE,'Restriction de divinité'!I23=TRUE),'Restriction de divinité'!H23,0)} -> 0
A24: Magni | C24: Corvus | G24: {=OR(C2:C4='Nom du personnage'!$F$51,C7:C13='Nom du personnage'!$F$51,C23='Nom du personnage'!$F$51)} -> FALSE | H24: Elûna | I24: =OR('Nom du personnage'!$F$60='Restriction de divinité'!$E$3,'Nom du personnage'!$F$60='Restriction de divinité'!$E$2) -> FALSE | K24: {=IF(AND(OR($G$2:$G$17='Nom du personnage'!$F$51)=FALSE,'Restriction de divinité'!G24=TRUE,'Restriction de divinité'!I24=TRUE),'Restriction de divinité'!H24,0)} -> 0
A25: Modi | C25: Rasgadan | G25: TRUE | H25: Leviastis | I25: ='Nom du personnage'!$F$60=$E$4 -> FALSE | K25: {=IF(AND(OR($G$2:$G$17='Nom du personnage'!$F$51)=FALSE,'Restriction de divinité'!G25=TRUE,'Restriction de divinité'!I25=TRUE),'Restriction de divinité'!H25,0)} -> 0
A26: Thrud | C26: Ratfolk | G26: =OR(C2='Nom du personnage'!$F$51,C13='Nom du personnage'!$F$51,C22='Nom du personnage'!$F$51) -> FALSE | H26: Lumer | I26: =OR('Nom du personnage'!$F$60='Restriction de divinité'!$E$3,'Nom du personnage'!$F$60='Restriction de divinité'!$E$2) -> FALSE | K26: {=IF(AND(OR($G$2:$G$17='Nom du personnage'!$F$51)=FALSE,'Restriction de divinité'!G26=TRUE,'Restriction de divinité'!I26=TRUE),'Restriction de divinité'!H26,0)} -> 0
A27: Vali | C27: Saurien (Phrynos) | G27: TRUE | H27: Magystia | I27: =OR('Nom du personnage'!$F$60='Restriction de divinité'!$E$3,'Nom du personnage'!$F$60='Restriction de divinité'!$E$2) -> FALSE | K27: {=IF(AND(OR($G$2:$G$17='Nom du personnage'!$F$51)=FALSE,'Restriction de divinité'!G27=TRUE,'Restriction de divinité'!I27=TRUE),'Restriction de divinité'!H27,0)} -> 0
A28: Vidar | C28: Saurien (Slann) | G28: TRUE | H28: Maskorino | I28: =TRUE -> TRUE | K28: {=IF(AND(OR($G$2:$G$17='Nom du personnage'!$F$51)=FALSE,'Restriction de divinité'!G28=TRUE,'Restriction de divinité'!I28=TRUE),'Restriction de divinité'!H28,0)} -> Maskorino
A29: Adramelech | C29: Saurien (Coatl) | G29: TRUE | H29: Myrkar | I29: =OR('Nom du personnage'!$F$60='Restriction de divinité'!$E$3,'Nom du personnage'!$F$60='Restriction de divinité'!$E$2) -> FALSE | K29: {=IF(AND(OR($G$2:$G$17='Nom du personnage'!$F$51)=FALSE,'Restriction de divinité'!G29=TRUE,'Restriction de divinité'!I29=TRUE),'Restriction de divinité'!H29,0)} -> 0
A30: Malveria | C30: Saurien (Troglodon) | G30: {=OR(C8:C11='Nom du personnage'!$F$51,C13:C17='Nom du personnage'!$F$51,C18:C31='Nom du personnage'!$F$51)} -> FALSE | H30: Thurdek | I30: =OR('Nom du personnage'!$F$60='Restriction de divinité'!$E$3,'Nom du personnage'!$F$60='Restriction de divinité'!$E$2) -> FALSE | K30: {=IF(AND(OR($G$2:$G$17='Nom du personnage'!$F$51)=FALSE,'Restriction de divinité'!G30=TRUE,'Restriction de divinité'!I30=TRUE),'Restriction de divinité'!H30,0)} -> 0
A31: Salazaar | C31: Morgull | G31: TRUE | H31: Vorn | I31: ='Nom du personnage'!$F$60=$E$4 -> FALSE | K31: {=IF(AND(OR($G$2:$G$17='Nom du personnage'!$F$51)=FALSE,'Restriction de divinité'!G31=TRUE,'Restriction de divinité'!I31=TRUE),'Restriction de divinité'!H31,0)} -> 0
A32: Thalia | G32: TRUE | H32: Walërya | I32: =OR('Nom du personnage'!$F$60='Restriction de divinité'!$E$4,'Nom du personnage'!$F$60='Restriction de divinité'!$E$2) -> FALSE | K32: {=IF(AND(OR($G$2:$G$17='Nom du personnage'!$F$51)=FALSE,'Restriction de divinité'!G32=TRUE,'Restriction de divinité'!I32=TRUE),'Restriction de divinité'!H32,0)} -> 0
A33: Essence Infernale | G33: {=OR(C2:C4='Nom du personnage'!$F$51,C6:C16='Nom du personnage'!$F$51,C18:C30='Nom du personnage'!$F$51)} -> FALSE | H33: Amida | I33: =OR('Nom du personnage'!$F$60='Restriction de divinité'!$E$3,'Nom du personnage'!$F$60='Restriction de divinité'!$E$2) -> FALSE | K33: {=IF(AND(OR($G$2:$G$17='Nom du personnage'!$F$51)=FALSE,'Restriction de divinité'!G33=TRUE,'Restriction de divinité'!I33=TRUE),'Restriction de divinité'!H33,0)} -> 0
A34: Esprits de la guerre | G34: TRUE | H34: Baku | I34: =OR('Nom du personnage'!$F$60='Restriction de divinité'!$E$3,'Nom du personnage'!$F$60='Restriction de divinité'!$E$2) -> FALSE | K34: {=IF(AND(OR($G$2:$G$17='Nom du personnage'!$F$51)=FALSE,'Restriction de divinité'!G34=TRUE,'Restriction de divinité'!I34=TRUE),'Restriction de divinité'!H34,0)} -> 0
A35: Esprits de la nature | G35: {=OR(C2:C7='Nom du personnage'!$F$51,C13='Nom du personnage'!$F$51,C22='Nom du personnage'!$F$51)} -> FALSE | H35: Izanagi & Izanami | I35: =OR('Nom du personnage'!$F$60='Restriction de divinité'!$E$4,'Nom du personnage'!$F$60='Restriction de divinité'!$E$2) -> FALSE | K35: {=IF(AND(OR($G$2:$G$17='Nom du personnage'!$F$51)=FALSE,'Restriction de divinité'!G35=TRUE,'Restriction de divinité'!I35=TRUE),'Restriction de divinité'!H35,0)} -> 0
A36: Esprits des morts | G36: TRUE | H36: O-Kuni-Nushi | I36: =TRUE -> TRUE | K36: {=IF(AND(OR($G$2:$G$17='Nom du personnage'!$F$51)=FALSE,'Restriction de divinité'!G36=TRUE,'Restriction de divinité'!I36=TRUE),'Restriction de divinité'!H36,0)} -> O-Kuni-Nushi
A37: Esprit de l'Aube | G37: {=OR(C2:C4='Nom du personnage'!$F$51,C7:C15='Nom du personnage'!$F$51,C18:C31='Nom du personnage'!$F$51)} -> FALSE | H37: Baldur | I37: ='Nom du personnage'!$F$60=$E$2 -> FALSE | K37: {=IF(AND(OR($G$2:$G$17='Nom du personnage'!$F$51)=FALSE,'Restriction de divinité'!G37=TRUE,'Restriction de divinité'!I37=TRUE),'Restriction de divinité'!H37,0)} -> 0
A38: Esprit de la Nuit | G38: TRUE | H38: Eir | I38: ='Nom du personnage'!$F$60=$E$2 -> FALSE | K38: {=IF(AND(OR($G$2:$G$17='Nom du personnage'!$F$51)=FALSE,'Restriction de divinité'!G38=TRUE,'Restriction de divinité'!I38=TRUE),'Restriction de divinité'!H38,0)} -> 0
G39: ='Nom du personnage'!$F$51='Restriction de divinité'!C13 -> FALSE | H39: Honir | I39: ='Nom du personnage'!$F$60=$E$3 -> FALSE | K39: {=IF(AND(OR($G$2:$G$17='Nom du personnage'!$F$51)=FALSE,'Restriction de divinité'!G39=TRUE,'Restriction de divinité'!I39=TRUE),'Restriction de divinité'!H39,0)} -> 0
G40: TRUE | H40: Magni | I40: =OR('Nom du personnage'!$F$60='Restriction de divinité'!$E$3,'Nom du personnage'!$F$60='Restriction de divinité'!$E$2) -> FALSE | K40: {=IF(AND(OR($G$2:$G$17='Nom du personnage'!$F$51)=FALSE,'Restriction de divinité'!G40=TRUE,'Restriction de divinité'!I40=TRUE),'Restriction de divinité'!H40,0)} -> 0
...

Sheet Données
A2: Événements | B2: XPs | C2: Races | D2: XPs raciaux | E2: PV jour | F2: PV nuit | H2: Carrières | I2: Armure permise | J2: Type d'armure | L2: Divinitées | N2: Moralité | Q2: Points de magie | R2: Semi-Magique | S2: Maximum Magique
A3: Mai | B3: 3 | C3: Demi-Elfe | D3: 28 | E3: 3 | F3: 3 | H3: Barbare | I3: 4 | J3: Toutes | L3: Arawn | N3: Bénéfique | P3: Barbare | Q3: 0 | R3: 0
A4: Juin | B4: 3 | C4: Elfe Gris | D4: 25 | E4: 3 | F4: 3 | H4: Combattant | I4: 8 | J4: Toutes | L4: Argonas | N4: Balancée | P4: Combatant | Q4: 0 | R4: 0
A5: Juillet | B5: 3 | C5: Elfe Lunaire | D5: 25 | E5: 3 | F5: 3 | H5: Druide | I5: 3 | J5: Non métallique | L5: Asmodérus | N5: Maléfique | P5: Druide | Q5: 20 | R5: 0 | S5: 10
A6: Août | B6: 3 | C6: Elfe Noir | D6: 25 | E6: 2 | F6: 4 | H6: Mage | I6: 0 | J6: Toutes | L6: Atem'ra | P6: Mage | Q6: 20 | R6: 0 | S6: 10
A7: Septembre | B7: 3 | C7: Elfe Sanguinaire | D7: 25 | E7: 3 | F7: 3 | H7: Marchand | I7: 3 | J7: Toutes | L7: Cyrder | P7: Marchand | Q7: 0 | R7: 0
A8: Octobre | B8: 3 | C8: Elfe Sauvage | D8: 25 | E8: 3 | F8: 3 | H8: Prêtre | I8: 5 | J8: Toutes | L8: Elûna | P8: Prêtre | Q8: 20 | R8: 0 | S8: 10
A9: Witcher's Den | B9: 3 | C9: Être Sylvestre (Terre) | D9: 25 | E9: 3 | F9: 3 | H9: Roublard | I9: 3 | J9: Toutes | L9: Leviastis | P9: Roublard | Q9: 0 | R9: 0
A10: Nuit de la terreur | B10: 3 | C10: Être Sylvestre (Eau) | D10: 25 | E10: 3 | F10: 3 | H10: Animiste | I10: 2 | J10: Toutes | L10: Lumer | P10: Animiste | Q10: 20 | R10: 0 | S10: 6
A11: Passe VIP | B11: 2 | C11: Être Sylvestre (Feu) | D11: 25 | E11: 3 | F11: 3 | H11: Archer | I11: 3 | J11: Toutes | L11: Magystia | P11: Archer | Q11: 0 | R11: 0
A12: Passe de saison | B12: 3 | C12: Être Sylvestre (Air) | D12: 25 | E12: 3 | F12: 3 | H12: Barde | I12: 3 | J12: Toutes | L12: Maskorino | P12: Barde | Q12: 10 | R12: 1 | S12: 5
C13: Haut-Elfe | D13: 25 | E13: 3 | F13: 3 | H13: Berserker | I13: 4 | J13: Toutes | L13: Myrkar | P13: Berserker | Q13: 0 | R13: 1
C14: Humain | D14: 30 | E14: 3 | F14: 3 | H14: Chaman | I14: 3 | J14: Toutes | L14: Thurdek | P14: Chaman | Q14: 20 | R14: 0 | S14: 6
C15: Nain | D15: 25 | E15: 4 | F15: 4 | H15: Charlatan | I15: 3 | J15: Toutes | L15: Vermilord | P15: Charlatan | Q15: 0 | R15: 0
C16: Gobelin | D16: 25 | E16: 2 | F16: 4 | H16: Ermite | I16: 2 | J16: Toutes | L16: Vorn | P16: Ermite | Q16: 10 | R16: 1 | S16: 5
C17: Orque | D17: 25 | E17: 3 | F17: 3 | H17: Garde | I17: 8 | J17: Toutes | L17: Walërya | P17: Garde | Q17: 0 | R17: 0
C18: Demi-Démon | D18: 25 | E18: 4 | F18: 4 | H18: Gardien Mystique | I18: 3 | J18: Non métallique | L18: Amida | P18: Gardien Mystique | Q18: 10 | R18: 1 | S18: 5
C19: Illithyd | D19: 25 | E19: 2 | F19: 4 | H19: Guérisseur | I19: 3 | J19: Toutes | L19: Baku | P19: Guérisseur | Q19: 10 | R19: 1 | S19: 5
C20: Norde | D20: 25 | E20: 4 | F20: 4 | H20: Inquisiteur | I20: 4 | J20: Toutes | L20: Izanagi & Izanami | P20: Inquisiteur | Q20: 10 | R20: 1 | S20: 5
C21: Presqu'Humain | D21: 25 | E21: 3 | F21: 3 | H21: Magelame | I21: 4 | J21: Toutes | L21: O-Kuni-Nushi | P21: Magelame | Q21: 10 | R21: 1 | S21: 5
C22: Bossu | D22: 25 | E22: 4 | F22: 4 | H22: Maître des runes | I22: 3 | J22: Toutes | L22: Baldur | P22: Maître des runes | Q22: 10 | R22: 1 | S22: 5
C23: Gitan | D23: 25 | E23: 3 | F23: 3 | H23: Maraudeur | I23: 8 | J23: Toutes | L23: Eir | P23: Maraudeur | Q23: 0 | R23: 0
C24: Arboréen | D24: 25 | E24: 3 | F24: 3 | H24: Paladin | I24: 8 | J24: Toutes | L24: Honir | P24: Paladin | Q24: 10 | R24: 1 | S24: 5
C25: Corvus | D25: 25 | E25: 3 | F25: 3 | H25: Rôdeur | I25: 3 | J25: Toutes | L25: Magni | P25: Rôdeur | Q25: 10 | R25: 1 | S25: 5
C26: Rasgadan | D26: 25 | E26: 4 | F26: 4 | H26: Sage | I26: 0 | J26: Toutes | L26: Modi | P26: Sage | Q26: 20 | R26: 0 | S26: 6
C27: Ratfolk | D27: 25 | E27: 2 | F27: 4 | H27: Scribe | I27: 0 | J27: Toutes | L27: Thrud | P27: Scribe | Q27: 10 | R27: 1 | S27: 5
C28: Saurien (Phrynos) | D28: 25 | E28: 3 | F28: 3 | H28: Seigneur de Guerre | I28: 8 | J28: Toutes | L28: Vali | P28: Seigneur de Guerre | Q28: 0 | R28: 0
C29: Saurien (Slann) | D29: 25 | E29: 3 | F29: 3 | H29: Totem | I29: 2 | J29: Toutes | L29: Vidar | P29: Totem | Q29: 10 | R29: 1 | S29: 5
C30: Saurien (Coatl) | D30: 25 | E30: 3 | F30: 3 | H30: Traqueur | I30: 3 | J30: Toutes | L30: Adramelech | P30: Traqueur | Q30: 0 | R30: 0
C31: Saurien (Troglodon) | D31: 25 | E31: 3 | F31: 3 | L31: Malveria
C32: Morgull | D32: 25 | E32: 3 | F32: 3 | L32: Salazaar
L33: Thalia
L34: Essence Infernale
L35: Esprits de la guerre
L36: Esprits de la nature
L37: Esprits des morts
L38: Esprit de l'Aube
L39: Esprit de la Nuit

Sheet Restriction de carrière
A2: Races | B2: Carrières
A3: Demi-Elfe | B3: Barbare | D3: Haut-Elfe | E3: Barbare | G3: =IF(D3='Nom du personnage'!$F$51,'Restriction de carrière'!E3,) -> 0 | H3: =IF(G3=0,0,2) -> 0
A4: Elfe Gris | B4: Combattant | D4: Haut-Elfe | E4: Combattant | G4: =IF(D4='Nom du personnage'!$F$51,'Restriction de carrière'!E4,) -> 0 | H4: =IF(G4=0,0,2) -> 0
A5: Elfe Lunaire | B5: Druide | D5: Haut-Elfe | E5: Druide | G5: =IF(D5='Nom du personnage'!$F$51,'Restriction de carrière'!E5,) -> 0 | H5: =IF(G5=0,0,2) -> 0
A6: Elfe Noir | B6: Mage | D6: Haut-Elfe | E6: Mage | G6: =IF(D6='Nom du personnage'!$F$51,'Restriction de carrière'!E6,) -> 0 | H6: =IF(G6=0,0,2) -> 0
A7: Elfe Sanguinaire | B7: Marchand | D7: Haut-Elfe | E7: Marchand | G7: =IF(D7='Nom du personnage'!$F$51,'Restriction de carrière'!E7,) -> 0 | H7: =IF(G7=0,0,2) -> 0
A8: Elfe Sauvage | B8: Prêtre | D8: Haut-Elfe | E8: Prêtre | G8: =IF(D8='Nom du personnage'!$F$51,'Restriction de carrière'!E8,) -> 0 | H8: =IF(G8=0,0,2) -> 0
A9: Être Sylvestre (Terre) | B9: Roublard | D9: Haut-Elfe | E9: Roublard | G9: =IF(D9='Nom du personnage'!$F$51,'Restriction de carrière'!E9,) -> 0 | H9: =IF(G9=0,0,2) -> 0
A10: Être Sylvestre (Eau) | B10: Animiste | D10: Haut-Elfe | E10: Animiste | G10: =IF(D10='Nom du personnage'!$F$51,'Restriction de carrière'!E10,) -> 0 | H10: =IF(G10=0,0,2) -> 0
A11: Être Sylvestre (Feu) | B11: Archer | D11: Haut-Elfe | E11: Archer | G11: =IF(D11='Nom du personnage'!$F$51,'Restriction de carrière'!E11,) -> 0 | H11: =IF(G11=0,0,2) -> 0
A12: Être Sylvestre (Air) | B12: Barde | D12: Haut-Elfe | E12: Chaman | G12: =IF(D12='Nom du personnage'!$F$51,'Restriction de carrière'!E12,) -> 0 | H12: =IF(G12=0,0,2) -> 0
A13: Haut-Elfe | B13: Berserker | D13: Haut-Elfe | E13: Charlatan | G13: =IF(D13='Nom du personnage'!$F$51,'Restriction de carrière'!E13,) -> 0 | H13: =IF(G13=0,0,2) -> 0
A14: Humain | B14: Chaman | D14: Haut-Elfe | E14: Ermite | G14: =IF(D14='Nom du personnage'!$F$51,'Restriction de carrière'!E14,) -> 0 | H14: =IF(G14=0,0,2) -> 0
... A30: Saurien (Coatl) | B30: Traqueur | D30: Norde | E30: Chaman | G30: =IF(D30='Nom du personnage'!$F$51,'Restriction de carrière'!E30,) -> 0 | H30: =IF(G30=0,0,2) -> 0
A31: Saurien (Troglodon) | D31: Norde | E31: Ermite | G31: =IF(D31='Nom du personnage'!$F$51,'Restriction de carrière'!E31,) -> 0 | H31: =IF(G31=0,0,2) -> 0
A32: Morgull | D32: Norde | E32: Gardien Mystique | G32: =IF(D32='Nom du personnage'!$F$51,'Restriction de carrière'!E32,) -> 0 | H32: =IF(G32=0,0,2) -> 0
D33: Norde | E33: Maître des runes | G33: =IF(D33='Nom du personnage'!$F$51,'Restriction de carrière'!E33,) -> 0 | H33: =IF(G33=0,0,2) -> 0
D34: Norde | E34: Paladin | G34: =IF(D34='Nom du personnage'!$F$51,'Restriction de carrière'!E34,) -> 0 | H34: =IF(G34=0,0,2) -> 0
D35: Norde | E35: Rôdeur | G35: =IF(D35='Nom du personnage'!$F$51,'Restriction de carrière'!E35,) -> 0 | H35: =IF(G35=0,0,2) -> 0
D36: Norde | E36: Seigneur de Guerre | G36: =IF(D36='Nom du personnage'!$F$51,'Restriction de carrière'!E36,) -> 0 | H36: =IF(G36=0,0,2) -> 0
D37: Norde | E37: Totem | G37: =IF(D37='Nom du personnage'!$F$51,'Restriction de carrière'!E37,) -> 0 | H37: =IF(G37=0,0,2) -> 0
D38: Norde | E38: Traqueur | G38: =IF(D38='Nom du personnage'!$F$51,'Restriction de carrière'!E38,) -> 0 | H38: =IF(G38=0,0,2) -> 0
D39: Elfe Gris | E39: Mage | G39: =IF(D39='Nom du personnage'!$F$51,'Restriction de carrière'!E39,) -> 0 | H39: =IF(G39=0,0,2) -> 0
D40: Elfe Gris | E40: Barde | G40: =IF(D40='Nom du personnage'!$F$51,'Restriction de carrière'!E40,) -> 0 | H40: =IF(G40=0,0,2) -> 0
D41: Elfe Gris | E41: Magelame | G41: =IF(D41='Nom du personnage'!$F$51,'Restriction de carrière'!E41,) -> 0 | H41: =IF(G41=0,0,2) -> 0
D42: Elfe Gris | E42: Maître des runes | G42: =IF(D42='Nom du personnage'!$F$51,'Restriction de carrière'!E42,) -> 0 | H42: =IF(G42=0,0,2) -> 0
D43: Elfe Gris | E43: Scribe | G43: =IF(D43='Nom du personnage'!$F$51,'Restriction de carrière'!E43,) -> 0 | H43: =IF(G43=0,0,2) -> 0
D44: Bossu | E44: Barbare | G44: =IF(D44='Nom du personnage'!$F$51,'Restriction de carrière'!E44,) -> 0 | H44: =IF(G44=0,0,2) -> 0
... D77: Rasgadan | E77: Traqueur | G77: =IF(D77='Nom du personnage'!$F$51,'Restriction de carrière'!E77,) -> 0 | H77: =IF(G77=0,0,2) -> 0
G78: =IF(SUM($H$3:$H$77)>0,0,B3) -> Barbare
G79: =IF(SUM($H$3:$H$68)>0,0,B4) -> Combattant
G80: =IF(SUM($H$3:$H$68)>0,0,B5) -> Druide
G81: =IF(SUM($H$3:$H$68)>0,0,B6) -> Mage
G82: =IF(SUM($H$3:$H$68)>0,0,B7) -> Marchand
G83: =IF(SUM($H$3:$H$68)>0,0,B8) -> Prêtre
G84: =IF(SUM($H$3:$H$68)>0,0,B9) -> Roublard
G85: =IF(SUM($H$3:$H$68)>0,0,B10) -> Animiste
G86: =IF(SUM($H$3:$H$68)>0,0,B11) -> Archer
G87: =IF(SUM($H$3:$H$68)>0,0,B12) -> Barde
G88: =IF(SUM($H$3:$H$68)>0,0,B13) -> Berserker
...

Sheet Religion
A2: Compétences
A3: Ambidexterie | C3: Religion | D3: =COUNTIF('Nom du personnage'!$C$66:$AC$85,Religion!C3) -> 0 | G3: {=OR('Nom du personnage'!$C$65:$L$85=Religion!C3,'Nom du personnage'!$Q$65:$Z$85=Religion!C3)} -> FALSE
A4: Archerie | C4: Religion (Bonus Druide) | D4: =COUNTIF('Nom du personnage'!$C$66:$AC$85,Religion!C4) -> 0 | E4: Druide | F4: =IF(E4='Nom du personnage'!$U$51,1,0) -> 0 | G4: {=OR('Nom du personnage'!$C$65:$L$85=Religion!C4,'Nom du personnage'!$Q$65:$Z$85=Religion!C4)} -> FALSE
A5: Archerie Arcane | C5: Religion (Bonus Mage) | D5: =COUNTIF('Nom du personnage'!$C$66:$AC$85,Religion!C5) -> 0 | E5: Mage | F5: =IF(E5='Nom du personnage'!$U$51,1,0) -> 0 | G5: {=OR('Nom du personnage'!$C$65:$L$85=Religion!C5,'Nom du personnage'!$Q$65:$Z$85=Religion!C5)} -> FALSE
A6: Arme à feu | C6: Religion (Bonus Prêtre) | D6: =COUNTIF('Nom du personnage'!$C$66:$AC$85,Religion!C6) -> 0 | E6: Prêtre | F6: =IF(E6='Nom du personnage'!$U$51,1,0) -> 0 | G6: {=OR('Nom du personnage'!$C$65:$L$85=Religion!C6,'Nom du personnage'!$Q$65:$Z$85=Religion!C6)} -> FALSE
A7: Arme de jet | C7: Religion (Bonus Animiste) | D7: =COUNTIF('Nom du personnage'!$C$66:$AC$85,Religion!C7) -> 0 | E7: Animiste | F7: =IF(E7='Nom du personnage'!$U$51,1,0) -> 0 | G7: {=OR('Nom du personnage'!$C$65:$L$85=Religion!C7,'Nom du personnage'!$Q$65:$Z$85=Religion!C7)} -> FALSE
A8: Arme non conventionnelle (2 mains) | C8: Religion (Bonus Barde) | D8: =COUNTIF('Nom du personnage'!$C$66:$AC$85,Religion!C8) -> 0 | E8: Barde | F8: =IF(E8='Nom du personnage'!$U$51,1,0) -> 0 | G8: {=OR('Nom du personnage'!$C$65:$L$85=Religion!C8,'Nom du personnage'!$Q$65:$Z$85=Religion!C8)} -> FALSE
A9: Arme non conventionnelle (Colossale) | C9: Religion (Bonus Berserker) | D9: =COUNTIF('Nom du personnage'!$C$66:$AC$85,Religion!C9) -> 0 | E9: Berserker | F9: =IF(E9='Nom du personnage'!$U$51,1,0) -> 0 | G9: {=OR('Nom du personnage'!$C$65:$L$85=Religion!C9,'Nom du personnage'!$Q$65:$Z$85=Religion!C9)} -> FALSE
A10: Art Mystique | C10: Religion (Bonus Chaman) | D10: =COUNTIF('Nom du personnage'!$C$66:$AC$85,Religion!C10) -> 0 | E10: Chaman | F10: =IF(E10='Nom du personnage'!$U$51,1,0) -> 0 | G10: {=OR('Nom du personnage'!$C$65:$L$85=Religion!C10,'Nom du personnage'!$Q$65:$Z$85=Religion!C10)} -> FALSE
A11: Bâton de pouvoir | C11: Religion (Bonus Ermite) | D11: =COUNTIF('Nom du personnage'!$C$66:$AC$85,Religion!C11) -> 0 | E11: Ermite | F11: =IF(E11='Nom du personnage'!$U$51,1,0) -> 0 | G11: {=OR('Nom du personnage'!$C$65:$L$85=Religion!C11,'Nom du personnage'!$Q$65:$Z$85=Religion!C11)} -> FALSE
A12: Bouclier | C12: Religion (Bonus Gardien Mystique) | D12: =COUNTIF('Nom du personnage'!$C$66:$AC$85,Religion!C12) -> 0 | E12: Gardien Mystique | F12: =IF(E12='Nom du personnage'!$U$51,1,0) -> 0 | G12: {=OR('Nom du personnage'!$C$65:$L$85=Religion!C12,'Nom du personnage'!$Q$65:$Z$85=Religion!C12)} -> FALSE
A13: Bravoure | C13: Religion (Bonus Guérisseur) | D13: =COUNTIF('Nom du personnage'!$C$66:$AC$85,Religion!C13) -> 0 | E13: Guérisseur | F13: =IF(E13='Nom du personnage'!$U$51,1,0) -> 0 | G13: {=OR('Nom du personnage'!$C$65:$L$85=Religion!C13,'Nom du personnage'!$Q$65:$Z$85=Religion!C13)} -> FALSE
A14: Charognard | C14: Religion (Bonus Inquisiteur) | D14: =COUNTIF('Nom du personnage'!$C$66:$AC$85,Religion!C14) -> 0 | E14: Inquisiteur | F14: =IF(E14='Nom du personnage'!$U$51,1,0) -> 0 | G14: {=OR('Nom du personnage'!$C$65:$L$85=Religion!C14,'Nom du personnage'!$Q$65:$Z$85=Religion!C14)} -> FALSE
A15: Concoction : Herboristerie | C15: Religion (Bonus Magelame) | D15: =COUNTIF('Nom du personnage'!$C$66:$AC$85,Religion!C15) -> 0 | E15: Magelame | F15: =IF(E15='Nom du personnage'!$U$51,1,0) -> 0 | G15: {=OR('Nom du personnage'!$C$65:$L$85=Religion!C15,'Nom du personnage'!$Q$65:$Z$85=Religion!C15)} -> FALSE
... A18: Endurance Simple | C18: Religion (Bonus Rôdeur) | D18: =COUNTIF('Nom du personnage'!$C$66:$AC$85,Religion!C18) -> 0 | E18: Rôdeur | F18: =IF(E18='Nom du personnage'!$U$51,1,0) -> 0 | G18: {=OR('Nom du personnage'!$C$65:$L$85=Religion!C18,'Nom du personnage'!$Q$65:$Z$85=Religion!C18)} -> FALSE
A19: Forge | C19: Religion (Bonus Sage) | D19: =COUNTIF('Nom du personnage'!$C$66:$AC$85,Religion!C19) -> 0 | G19: {=OR('Nom du personnage'!$C$65:$L$85=Religion!C19,'Nom du personnage'!$Q$65:$Z$85=Religion!C19)} -> FALSE
A20: Héraldique | C20: Religion (Bonus Scribe) | D20: =COUNTIF('Nom du personnage'!$C$66:$AC$85,Religion!C20) -> 0 | E20: Scribe | F20: =IF(E20='Nom du personnage'!$U$51,1,0) -> 0 | G20: {=OR('Nom du personnage'!$C$65:$L$85=Religion!C20,'Nom du personnage'!$Q$65:$Z$85=Religion!C20)} -> FALSE
A21: Invocation Guerrière | C21: Religion (Bonus Totem) | D21: =COUNTIF('Nom du personnage'!$C$66:$AC$85,Religion!C21) -> 0 | E21: Totem | F21: =IF(E21='Nom du personnage'!$U$51,1,0) -> 0 | G21: {=OR('Nom du personnage'!$C$65:$L$85=Religion!C21,'Nom du personnage'!$Q$65:$Z$85=Religion!C21)} -> FALSE
A22: Lecture et écriture (Commun) | C22: Total | D22: =SUM(D3:D21) -> 0 | F22: =SUM(F3:F21) -> 0
A23: Lecture et écriture (Elfique) | C23: Pts religion | D23: =+D22>=1 -> FALSE
A24: Lecture et écriture (Rakuzan) | C24: Pts religion | D24: =+D22=2 -> FALSE
A25: Lecture et écriture (Infernal) | C25: Religion 1 | D25: =ISBLANK('Nom du personnage'!F54) -> TRUE
A26: Lecture et écriture (Céleste) | C26: Religion 2 | D26: =ISBLANK('Nom du personnage'!K54) -> TRUE
A27: Lecture et écriture (Outremonde) | C27: Final Religion 1 | D27: =IF(D25=TRUE,TRUE,IF(AND(D23=TRUE,D25=FALSE),TRUE,FALSE)) -> TRUE
A28: Lecture et écriture (Vermilangue) | C28: Final Religion 2 | D28: =IF(D26=TRUE,TRUE,IF(AND(D24=TRUE,D26=FALSE),TRUE,FALSE)) -> TRUE
A29: Lecture et écriture (Orque) | C29: Religion présente | D29: {=OR(G3:G21=TRUE)} -> FALSE
A30: Lecture et écriture (Arcane)
A31: Lecture et écriture (Arborique)
A32: Lecture et écriture (Runique)
A33: Lecture et écriture (Sylvestre)
A34: Mulet de bataille
A35: Noblesse
A36: Peinture des Morts
A37: Rage animale
A38: Religion
A39: Résistance à l'alcool
A40: Résistance aux maladies
A41: Rituel
... A1081: Arme de jet (Bonus Traqueur)

Sheet Restriction de moralité
A1: Races | B1: Moralité
A2: Demi-Elfe | B2: Bénéfique | D2: Elfe Lunaire | E2: Bénéfique | G2: =IF(D2='Nom du personnage'!$F$51,E2,) -> 0 | H2: =IF(G2=0,0,2) -> 0
A3: Elfe Gris | B3: Balancée | D3: Elfe Lunaire | E3: Balancée | G3: =IF(D3='Nom du personnage'!$F$51,E3,) -> 0 | H3: =IF(G3=0,0,2) -> 0
A4: Elfe Lunaire | B4: Maléfique | D4: Elfe Noir | E4: Balancée | G4: =IF(D4='Nom du personnage'!$F$51,E4,) -> 0 | H4: =IF(G4=0,0,2) -> 0
A5: Elfe Noir | D5: Elfe Noir | E5: Maléfique | G5: =IF(D5='Nom du personnage'!$F$51,E5,) -> 0 | H5: =IF(G5=0,0,2) -> 0
A6: Elfe Sanguinaire | D6: Elfe Sanguinaire | E6: Balancée | G6: =IF(D6='Nom du personnage'!$F$51,E6,) -> 0 | H6: =IF(G6=0,0,2) -> 0
A7: Elfe Sauvage | D7: Elfe Sanguinaire | E7: Maléfique | G7: =IF(D7='Nom du personnage'!$F$51,E7,) -> 0 | H7: =IF(G7=0,0,2) -> 0
A8: Être Sylvestre (Terre) | D8: Orque | E8: Balancée | G8: =IF(D8='Nom du personnage'!$F$51,E8,) -> 0 | H8: =IF(G8=0,0,2) -> 0
A9: Être Sylvestre (Eau) | D9: Orque | E9: Maléfique | G9: =IF(D9='Nom du personnage'!$F$51,E9,) -> 0 | H9: =IF(G9=0,0,2) -> 0
A10: Être Sylvestre (Feu) | D10: Demi-Démon | E10: Balancée | G10: =IF(D10='Nom du personnage'!$F$51,E10,) -> 0 | H10: =IF(G10=0,0,2) -> 0
A11: Être Sylvestre (Air) | D11: Demi-Démon | E11: Maléfique | G11: =IF(D11='Nom du personnage'!$F$51,E11,) -> 0 | H11: =IF(G11=0,0,2) -> 0
A12: Haut-Elfe | D12: Illithyd | E12: Maléfique | G12: =IF(D12='Nom du personnage'!$F$51,E12,) -> 0 | H12: =IF(G12=0,0,2) -> 0
A13: Humain | D13: Norde | E13: Balancée | G13: =IF(D13='Nom du personnage'!$F$51,E13,) -> 0 | H13: =IF(G13=0,0,2) -> 0
A14: Nain | D14: Norde | E14: Maléfique | G14: =IF(D14='Nom du personnage'!$F$51,E14,) -> 0 | H14: =IF(G14=0,0,2) -> 0
A15: Gobelin | D15: Morgull | E15: Balancée | G15: =IF(D15='Nom du personnage'!$F$51,E15,) -> 0 | H15: =IF(G15=0,0,2) -> 0
A16: Orque | D16: Morgull | E16: Maléfique | G16: =IF(D16='Nom du personnage'!$F$51,E16,) -> 0 | H16: =IF(G16=0,0,2) -> 0
A17: Demi-Démon | G17: =IF(D17='Nom du personnage'!$F$51,E17,) -> 0 | H17: =IF(G17=0,0,2) -> 0
A18: Illithyd | G18: =IF(SUM($H$2:$H$76)>0,0,B2) -> Bénéfique
A19: Norde | G19: =IF(SUM($H$2:$H$76)>0,0,B3) -> Balancée
A20: Presqu'Humain | G20: =IF(SUM($H$2:$H$76)>0,0,B4) -> Maléfique
A21: Bossu
A22: Gitan
A23: Arboréen
A24: Corvus
A25: Rasgadan
A26: Ratfolk
A27: Saurien (Phrynos)
A28: Saurien (Slann)
A29: Saurien (Coatl)
A30: Saurien (Troglodon)
A31: Morgull

Sheet Compétences raciales
B2: Compétence | O2: Compétence
B3: {='Nom du personnage'!C66:L66} -> 0 | C3: 0 | D3: 0 | E3: 0 | F3: 0 | G3: 0 | H3: 0 | I3: 0 | J3: 0 | K3: 0 | L3: =ISERROR(VLOOKUP(B3,Compétences!$T$3:$V$68,2,FALSE)) -> TRUE | M3: =IF(L3,0,-1) -> 0 | O3: {='Nom du personnage'!Q66:Z66} -> 0 | P3: 0 | Q3: 0 | R3: 0 | S3: 0 | T3: 0 | U3: 0 | V3: 0 | W3: 0 | X3: 0 | Y3: =ISERROR(VLOOKUP(O3,Compétences!$T$3:$V$68,2,FALSE)) -> TRUE | Z3: =IF(Y3,0,-1) -> 0
B4: {='Nom du personnage'!C67:L67} -> 0 | C4: 0 | D4: 0 | E4: 0 | F4: 0 | G4: 0 | H4: 0 | I4: 0 | J4: 0 | K4: 0 | L4: =ISERROR(VLOOKUP(B4,Compétences!$T$3:$V$68,2,FALSE)) -> TRUE | M4: =IF(L4,0,-1) -> 0 | O4: {='Nom du personnage'!Q67:Z67} -> 0 | P4: 0 | Q4: 0 | R4: 0 | S4: 0 | T4: 0 | U4: 0 | V4: 0 | W4: 0 | X4: 0 | Y4: =ISERROR(VLOOKUP(O4,Compétences!$T$3:$V$68,2,FALSE)) -> TRUE | Z4: =IF(Y4,0,-1) -> 0
B5: {='Nom du personnage'!C68:L68} -> 0 | C5: 0 | D5: 0 | E5: 0 | F5: 0 | G5: 0 | H5: 0 | I5: 0 | J5: 0 | K5: 0 | L5: =ISERROR(VLOOKUP(B5,Compétences!$T$3:$V$68,2,FALSE)) -> TRUE | M5: =IF(L5,0,-1) -> 0 | O5: {='Nom du personnage'!Q68:Z68} -> 0 | P5: 0 | Q5: 0 | R5: 0 | S5: 0 | T5: 0 | U5: 0 | V5: 0 | W5: 0 | X5: 0 | Y5: =ISERROR(VLOOKUP(O5,Compétences!$T$3:$V$68,2,FALSE)) -> TRUE | Z5: =IF(Y5,0,-1) -> 0
B6: {='Nom du personnage'!C69:L69} -> 0 | C6: 0 | D6: 0 | E6: 0 | F6: 0 | G6: 0 | H6: 0 | I6: 0 | J6: 0 | K6: 0 | L6: =ISERROR(VLOOKUP(B6,Compétences!$T$3:$V$68,2,FALSE)) -> TRUE | M6: =IF(L6,0,-1) -> 0 | O6: {='Nom du personnage'!Q69:Z69} -> 0 | P6: 0 | Q6: 0 | R6: 0 | S6: 0 | T6: 0 | U6: 0 | V6: 0 | W6: 0 | X6: 0 | Y6: =ISERROR(VLOOKUP(O6,Compétences!$T$3:$V$68,2,FALSE)) -> TRUE | Z6: =IF(Y6,0,-1) -> 0
B7: {='Nom du personnage'!C70:L70} -> 0 | C7: 0 | D7: 0 | E7: 0 | F7: 0 | G7: 0 | H7: 0 | I7: 0 | J7: 0 | K7: 0 | L7: =ISERROR(VLOOKUP(B7,Compétences!$T$3:$V$68,2,FALSE)) -> TRUE | M7: =IF(L7,0,-1) -> 0 | O7: {='Nom du personnage'!Q70:Z70} -> 0 | P7: 0 | Q7: 0 | R7: 0 | S7: 0 | T7: 0 | U7: 0 | V7: 0 | W7: 0 | X7: 0 | Y7: =ISERROR(VLOOKUP(O7,Compétences!$T$3:$V$68,2,FALSE)) -> TRUE | Z7: =IF(Y7,0,-1) -> 0
B8: {='Nom du personnage'!C71:L71} -> 0 | C8: 0 | D8: 0 | E8: 0 | F8: 0 | G8: 0 | H8: 0 | I8: 0 | J8: 0 | K8: 0 | L8: =ISERROR(VLOOKUP(B8,Compétences!$T$3:$V$68,2,FALSE)) -> TRUE | M8: =IF(L8,0,-1) -> 0 | O8: {='Nom du personnage'!Q71:Z71} -> 0 | P8: 0 | Q8: 0 | R8: 0 | S8: 0 | T8: 0 | U8: 0 | V8: 0 | W8: 0 | X8: 0 | Y8: =ISERROR(VLOOKUP(O8,Compétences!$T$3:$V$68,2,FALSE)) -> TRUE | Z8: =IF(Y8,0,-1) -> 0
B9: {='Nom du personnage'!C72:L72} -> 0 | C9: 0 | D9: 0 | E9: 0 | F9: 0 | G9: 0 | H9: 0 | I9: 0 | J9: 0 | K9: 0 | L9: =ISERROR(VLOOKUP(B9,Compétences!$T$3:$V$68,2,FALSE)) -> TRUE | M9: =IF(L9,0,-1) -> 0 | O9: {='Nom du personnage'!Q72:Z72} -> 0 | P9: 0 | Q9: 0 | R9: 0 | S9: 0 | T9: 0 | U9: 0 | V9: 0 | W9: 0 | X9: 0 | Y9: =ISERROR(VLOOKUP(O9,Compétences!$T$3:$V$68,2,FALSE)) -> TRUE | Z9: =IF(Y9,0,-1) -> 0
B10: {='Nom du personnage'!C73:L73} -> 0 | C10: 0 | D10: 0 | E10: 0 | F10: 0 | G10: 0 | H10: 0 | I10: 0 | J10: 0 | K10: 0 | L10: =ISERROR(VLOOKUP(B10,Compétences!$T$3:$V$68,2,FALSE)) -> TRUE | M10: =IF(L10,0,-1) -> 0 | O10: {='Nom du personnage'!Q73:Z73} -> 0 | P10: 0 | Q10: 0 | R10: 0 | S10: 0 | T10: 0 | U10: 0 | V10: 0 | W10: 0 | X10: 0 | Y10: =ISERROR(VLOOKUP(O10,Compétences!$T$3:$V$68,2,FALSE)) -> TRUE | Z10: =IF(Y10,0,-1) -> 0
B11: {='Nom du personnage'!C74:L74} -> 0 | C11: 0 | D11: 0 | E11: 0 | F11: 0 | G11: 0 | H11: 0 | I11: 0 | J11: 0 | K11: 0 | L11: =ISERROR(VLOOKUP(B11,Compétences!$T$3:$V$68,2,FALSE)) -> TRUE | M11: =IF(L11,0,-1) -> 0 | O11: {='Nom du personnage'!Q74:Z74} -> 0 | P11: 0 | Q11: 0 | R11: 0 | S11: 0 | T11: 0 | U11: 0 | V11: 0 | W11: 0 | X11: 0 | Y11: =ISERROR(VLOOKUP(O11,Compétences!$T$3:$V$68,2,FALSE)) -> TRUE | Z11: =IF(Y11,0,-1) -> 0
B12: {='Nom du personnage'!C75:L75} -> 0 | C12: 0 | D12: 0 | E12: 0 | F12: 0 | G12: 0 | H12: 0 | I12: 0 | J12: 0 | K12: 0 | L12: =ISERROR(VLOOKUP(B12,Compétences!$T$3:$V$68,2,FALSE)) -> TRUE | M12: =IF(L12,0,-1) -> 0 | O12: {='Nom du personnage'!Q75:Z75} -> 0 | P12: 0 | Q12: 0 | R12: 0 | S12: 0 | T12: 0 | U12: 0 | V12: 0 | W12: 0 | X12: 0 | Y12: =ISERROR(VLOOKUP(O12,Compétences!$T$3:$V$68,2,FALSE)) -> TRUE | Z12: =IF(Y12,0,-1) -> 0
B13: {='Nom du personnage'!C76:L76} -> 0 | C13: 0 | D13: 0 | E13: 0 | F13: 0 | G13: 0 | H13: 0 | I13: 0 | J13: 0 | K13: 0 | L13: =ISERROR(VLOOKUP(B13,Compétences!$T$3:$V$68,2,FALSE)) -> TRUE | M13: =IF(L13,0,-1) -> 0 | O13: {='Nom du personnage'!Q76:Z76} -> 0 | P13: 0 | Q13: 0 | R13: 0 | S13: 0 | T13: 0 | U13: 0 | V13: 0 | W13: 0 | X13: 0 | Y13: =ISERROR(VLOOKUP(O13,Compétences!$T$3:$V$68,2,FALSE)) -> TRUE | Z13: =IF(Y13,0,-1) -> 0
B14: {='Nom du personnage'!C77:L77} -> 0 | C14: 0 | D14: 0 | E14: 0 | F14: 0 | G14: 0 | H14: 0 | I14: 0 | J14: 0 | K14: 0 | L14: =ISERROR(VLOOKUP(B14,Compétences!$T$3:$V$68,2,FALSE)) -> TRUE | M14: =IF(L14,0,-1) -> 0 | O14: {='Nom du personnage'!Q77:Z77} -> 0 | P14: 0 | Q14: 0 | R14: 0 | S14: 0 | T14: 0 | U14: 0 | V14: 0 | W14: 0 | X14: 0 | Y14: =ISERROR(VLOOKUP(O14,Compétences!$T$3:$V$68,2,FALSE)) -> TRUE | Z14: =IF(Y14,0,-1) -> 0
... B22: {='Nom du personnage'!C85:L85} -> 0 | C22: 0 | D22: 0 | E22: 0 | F22: 0 | G22: 0 | H22: 0 | I22: 0 | J22: 0 | K22: 0 | L22: =ISERROR(VLOOKUP(B22,Compétences!$T$3:$V$68,2,FALSE)) -> TRUE | M22: =IF(L22,0,-1) -> 0 | O22: {='Nom du personnage'!Q85:Z85} -> 0 | P22: 0 | Q22: 0 | R22: 0 | S22: 0 | T22: 0 | U22: 0 | V22: 0 | W22: 0 | X22: 0 | Y22: =ISERROR(VLOOKUP(O22,Compétences!$T$3:$V$68,2,FALSE)) -> TRUE | Z22: =IF(Y22,0,-1) -> 0

Sheet Compétences
A2: Catégories | B2: Compétences | C2: Xps | H2: Compétences | I2: Xps | J2: Catégories | K2: Cummulable | M2: Compétences | N2: Xps | O2: Xps +1 | P2: Catégorie | Q2: Race | R2: Compétence | T2: Compétences | U2: XP | V2: Race
A3: Barbare | B3: Attaque brutale | C3: 6 | D3: 1 | H3: Ambidexterie | I3: 3 | J3: ='Nom du personnage'!$U$51 -> 0 | K3: 5 | M3: =IF('Bonus Humain'!H4=0,IF(P3=J3,H3,),'Bonus Humain'!D4) -> Ambidexterie | N3: =IF(M3='Bonus Humain'!D4,Compétences!I3-1,VLOOKUP(M3,H3:J60,2,FALSE)) -> 3 | O3: =VLOOKUP(M3,H3:J60,2,FALSE) -> 3 | P3: ='Nom du personnage'!$U$51 -> 0 | Q3: Demi-Elfe | R3: Archerie | T3: =+IF(V3=Q3,R3,"N/A") -> N/A | U3: -1 | V3: {='Nom du personnage'!$F$51:$O$51} -> 0 | W3: 0 | X3: 0 | Y3: 0 | Z3: 0 | AA3: 0 | AB3: 0 | AC3: 0 | AD3: 0 | AE3: 0
A4: Barbare | B4: Bravoure accrue | C4: 6 | D4: 1 | H4: Archerie | I4: 3 | J4: ='Nom du personnage'!$U$51 -> 0 | K4: 5 | M4: =IF('Bonus Humain'!H5=0,IF(P4=J4,H4,),'Bonus Humain'!D5) -> Archerie | N4: =IF(M4='Bonus Humain'!D5,Compétences!I4-1,VLOOKUP(M4,H4:J61,2,FALSE)) -> 3 | O4: =VLOOKUP(M4,H4:J61,2,FALSE) -> 3 | P4: ='Nom du personnage'!$U$51 -> 0 | Q4: Demi-Elfe | R4: Lecture et écriture (Commun) | T4: =+IF(V4=Q4,R4,"N/A") -> N/A | U4: -1 | V4: {='Nom du personnage'!$F$51:$O$51} -> 0 | W4: 0 | X4: 0 | Y4: 0 | Z4: 0 | AA4: 0 | AB4: 0 | AC4: 0 | AD4: 0 | AE4: 0
A5: Barbare | B5: Bris d'arme | C5: 6 | D5: 1 | H5: Archerie Arcane | I5: 4 | J5: ='Nom du personnage'!$U$51 -> 0 | K5: 1 | M5: =IF('Bonus Humain'!H6=0,IF(COUNTIF('Nom du personnage'!C66:AC85,Compétences!M4)>0,Compétences!H5,0),'Bonus Humain'!D6) -> 0 | N5: =IF(M5='Bonus Humain'!D6,Compétences!I5-1,VLOOKUP(M5,H5:J62,2,FALSE)) -> #N/A | O5: =VLOOKUP(M5,H5:J62,2,FALSE) -> #N/A | P5: ='Nom du personnage'!$U$51 -> 0 | Q5: Demi-Elfe | R5: Lecture et écriture (Elfique) | T5: =+IF(V5=Q5,R5,"N/A") -> N/A | U5: -1 | V5: {='Nom du personnage'!$F$51:$O$51} -> 0 | W5: 0 | X5: 0 | Y5: 0 | Z5: 0 | AA5: 0 | AB5: 0 | AC5: 0 | AD5: 0 | AE5: 0
A6: Barbare | B6: Brise-bouclier | C6: 6 | D6: 1 | H6: Arme à feu | I6: 3 | J6: ='Nom du personnage'!$U$51 -> 0 | K6: 5 | M6: =IF('Bonus Humain'!H7=0,IF(P6=J6,H6,),'Bonus Humain'!D7) -> Arme à feu | N6: =IF(M6='Bonus Humain'!D7,Compétences!I6-1,VLOOKUP(M6,H6:J63,2,FALSE)) -> 3 | O6: =VLOOKUP(M6,H6:J63,2,FALSE) -> 3 | P6: ='Nom du personnage'!$U$51 -> 0 | Q6: Demi-Elfe | R6: Lecture et écriture (Rakuzan) | T6: =+IF(V6=Q6,R6,"N/A") -> N/A | U6: -1 | V6: {='Nom du personnage'!$F$51:$O$51} -> 0 | W6: 0 | X6: 0 | Y6: 0 | Z6: 0 | AA6: 0 | AB6: 0 | AC6: 0 | AD6: 0 | AE6: 0
A7: Barbare | B7: Charge | C7: 5 | D7: 5 | H7: Arme de jet | I7: 3 | J7: ='Nom du personnage'!$U$51 -> 0 | K7: 5 | M7: =IF('Bonus Humain'!H8=0,IF(P7=J7,H7,),'Bonus Humain'!D8) -> Arme de jet | N7: =IF(M7='Bonus Humain'!D8,Compétences!I7-1,VLOOKUP(M7,H7:J64,2,FALSE)) -> 3 | O7: =VLOOKUP(M7,H7:J64,2,FALSE) -> 3 | P7: ='Nom du personnage'!$U$51 -> 0 | Q7: Demi-Elfe | R7: Lecture et écriture (Infernal) | T7: =+IF(V7=Q7,R7,"N/A") -> N/A | U7: -1 | V7: {='Nom du personnage'!$F$51:$O$51} -> 0 | W7: 0 | X7: 0 | Y7: 0 | Z7: 0 | AA7: 0 | AB7: 0 | AC7: 0 | AD7: 0 | AE7: 0
A8: Barbare | B8: Charge accrue | C8: 6 | D8: 5 | H8: Arme non conventionnelle - 2 mains | I8: 4 | J8: ='Nom du personnage'!$U$51 -> 0 | K8: 5 | M8: =IF('Bonus Humain'!H9=0,IF(P8=J8,H8,),'Bonus Humain'!D9) -> Arme non conventionnelle - 2 mains | N8: =IF(M8='Bonus Humain'!D9,Compétences!I8-1,VLOOKUP(M8,H8:J65,2,FALSE)) -> 4 | O8: =VLOOKUP(M8,H8:J65,2,FALSE) -> 4 | P8: ='Nom du personnage'!$U$51 -> 0 | Q8: Demi-Elfe | R8: Lecture et écriture (Céleste) | T8: =+IF(V8=Q8,R8,"N/A") -> N/A | U8: -1 | V8: {='Nom du personnage'!$F$51:$O$51} -> 0 | W8: 0 | X8: 0 | Y8: 0 | Z8: 0 | AA8: 0 | AB8: 0 | AC8: 0 | AD8: 0 | AE8: 0
A9: Barbare | B9: Coup meurtrier | C9: 4 | D9: 1 | H9: Arme non conventionnelle - Colossale | I9: 2 | J9: ='Nom du personnage'!$U$51 -> 0 | K9: 5 | M9: =IF('Bonus Humain'!H10=0,IF(COUNTIF('Nom du personnage'!C66:AC85,Compétences!M8)>0,Compétences!H9,0),'Bonus Humain'!D10) -> 0 | N9: =IF(M9='Bonus Humain'!D10,Compétences!I9-1,VLOOKUP(M9,H9:J66,2,FALSE)) -> #N/A | O9: =VLOOKUP(M9,H9:J66,2,FALSE) -> #N/A | P9: ='Nom du personnage'!$U$51 -> 0 | Q9: Demi-Elfe | R9: Lecture et écriture (Outremonde) | T9: =+IF(V9=Q9,R9,"N/A") -> N/A | U9: -1 | V9: {='Nom du personnage'!$F$51:$O$51} -> 0 | W9: 0 | X9: 0 | Y9: 0 | Z9: 0 | AA9: 0 | AB9: 0 | AC9: 0 | AD9: 0 | AE9: 0
A10: Barbare | B10: Coup puissant | C10: 5 | D10: 5 | H10: Art Mystique | I10: 2 | J10: ='Nom du personnage'!$U$51 -> 0 | K10: 1 | M10: =IF('Bonus Humain'!H11=0,IF('Compétences raciales + carrière'!B36>0,Compétences!H10,0),'Bonus Humain'!D11) -> 0 | N10: =IF(M10='Bonus Humain'!D11,Compétences!I10-1,VLOOKUP(M10,H10:J67,2,FALSE)) -> #N/A | O10: =VLOOKUP(M10,H10:J67,2,FALSE) -> #N/A | P10: ='Nom du personnage'!$U$51 -> 0 | Q10: Demi-Elfe | R10: Lecture et écriture (Vermilangue) | T10: =+IF(V10=Q10,R10,"N/A") -> N/A | U10: -1 | V10: {='Nom du personnage'!$F$51:$O$51} -> 0 | W10: 0 | X10: 0 | Y10: 0 | Z10: 0 | AA10: 0 | AB10: 0 | AC10: 0 | AD10: 0 | AE10: 0
A11: Barbare | B11: Endurance guerrière | C11: 3 | D11: 5 | H11: Bâton de pouvoir | I11: 6 | J11: ='Nom du personnage'!$U$51 -> 0 | K11: 5 | M11: =IF('Bonus Humain'!H12=0,IF(ISERROR(IF(VLOOKUP('Nom du personnage'!$U$51,Données!P3:S30,2,FALSE)>0,Compétences!H11,0)=TRUE),0,IF(VLOOKUP('Nom du personnage'!$U$51,Données!P3:S30,2,FALSE)>0,Compétences!H11,0)),'Bonus Humain'!D12) -> 0 | N11: =IF(M11='Bonus Humain'!D12,Compétences!I11-1,VLOOKUP(M11,H11:J68,2,FALSE)) -> #N/A | O11: =VLOOKUP(M11,H11:J68,2,FALSE) -> #N/A | P11: ='Nom du personnage'!$U$51 -> 0 | Q11: Demi-Elfe | R11: Lecture et écriture (Orque) | T11: =+IF(V11=Q11,R11,"N/A") -> N/A | U11: -1 | V11: {='Nom du personnage'!$F$51:$O$51} -> 0 | W11: 0 | X11: 0 | Y11: 0 | Z11: 0 | AA11: 0 | AB11: 0 | AC11: 0 | AD11: 0 | AE11: 0
A12: Barbare | B12: Maître abidextre | C12: 2 | D12: 5 | H12: Bouclier | I12: 2 | J12: ='Nom du personnage'!$U$51 -> 0 | K12: 5 | M12: =IF('Bonus Humain'!H13=0,IF(P12=J12,H12,),'Bonus Humain'!D13) -> Bouclier | N12: =IF(M12='Bonus Humain'!D13,Compétences!I12-1,VLOOKUP(M12,H12:J69,2,FALSE)) -> 2 | O12: =VLOOKUP(M12,H12:J69,2,FALSE) -> 2 | P12: ='Nom du personnage'!$U$51 -> 0 | Q12: Demi-Elfe | R12: Lecture et écriture (Arcane) | T12: =+IF(V12=Q12,R12,"N/A") -> N/A | U12: -1 | V12: {='Nom du personnage'!$F$51:$O$51} -> 0 | W12: 0 | X12: 0 | Y12: 0 | Z12: 0 | AA12: 0 | AB12: 0 | AC12: 0 | AD12: 0 | AE12: 0
A13: Barbare | B13: Onde de choc | C13: 6 | D13: 1 | H13: Bravoure | I13: 4 | J13: ='Nom du personnage'!$U$51 -> 0 | K13: 5 | M13: =IF('Bonus Humain'!H14=0,IF(P13=J13,H13,),'Bonus Humain'!D14) -> Bravoure | N13: =IF(M13='Bonus Humain'!D14,Compétences!I13-1,VLOOKUP(M13,H13:J70,2,FALSE)) -> 4 | O13: =VLOOKUP(M13,H13:J70,2,FALSE) -> 4 | P13: ='Nom du personnage'!$U$51 -> 0 | Q13: Demi-Elfe | R13: Lecture et écriture (Arborique) | T13: =+IF(V13=Q13,R13,"N/A") -> N/A | U13: -1 | V13: {='Nom du personnage'!$F$51:$O$51} -> 0 | W13: 0 | X13: 0 | Y13: 0 | Z13: 0 | AA13: 0 | AB13: 0 | AC13: 0 | AD13: 0 | AE13: 0
A14: Barbare | B14: Peinture de protection | C14: 4 | D14: 1 | H14: Charognard | I14: 4 | J14: ='Nom du personnage'!$U$51 -> 0 | K14: 1 | M14: =IF('Bonus Humain'!H15=0,IF('Compétences raciales + carrière'!B29=1,Compétences!H14,0),'Bonus Humain'!D15) -> 0 | N14: =IF(M14='Bonus Humain'!D15,Compétences!I14-1,VLOOKUP(M14,H14:J71,2,FALSE)) -> #N/A | O14: =VLOOKUP(M14,H14:J71,2,FALSE) -> #N/A | P14: ='Nom du personnage'!$U$51 -> 0 | Q14: Demi-Elfe | R14: Lecture et écriture (Runique) | T14: =+IF(V14=Q14,R14,"N/A") -> N/A | U14: -1 | V14: {='Nom du personnage'!$F$51:$O$51} -> 0 | W14: 0 | X14: 0 | Y14: 0 | Z14: 0 | AA14: 0 | AB14: 0 | AC14: 0 | AD14: 0 | AE14: 0
A15: Barbare | B15: Résistance à la torture | C15: 4 | D15: 1 | H15: Concoction : Herboristerie | I15: 5 | J15: ='Nom du personnage'!$U$51 -> 0 | K15: 5 | M15: =Concoction!J20 -> 0 | N15: =IF(M15='Bonus Humain'!D16,Compétences!I15-1,VLOOKUP(M15,H15:J72,2,FALSE)) -> #N/A | O15: =N15 -> #N/A | P15: ='Nom du personnage'!$U$51 -> 0 | Q15: Demi-Elfe | R15: Lecture et écriture (Sylvestre) | T15: =+IF(V15=Q15,R15,"N/A") -> N/A | U15: -1 | V15: {='Nom du personnage'!$F$51:$O$51} -> 0 | W15: 0 | X15: 0 | Y15: 0 | Z15: 0 | AA15: 0 | AB15: 0 | AC15: 0 | AD15: 0 | AE15: 0
A16: Barbare | B16: Résistance physique | C16: 6 | D16: 1 | H16: Concoction : Alchimie | I16: 5 | J16: ='Nom du personnage'!$U$51 -> 0 | K16: 5 | M16: =Concoction!J21 -> 0 | N16: =IF(M16='Bonus Humain'!D17,Compétences!I16-1,VLOOKUP(M16,H16:J73,2,FALSE)) -> #N/A | O16: =N16 -> #N/A | P16: ='Nom du personnage'!$U$51 -> 0 | Q16: Elfe Gris | R16: Lecture et écriture (Commun) | T16: =+IF(V16=Q16,R16,"N/A") -> N/A | U16: -1 | V16: {='Nom du personnage'!$F$51:$O$51} -> 0 | W16: 0 | X16: 0 | Y16: 0 | Z16: 0 | AA16: 0 | AB16: 0 | AC16: 0 | AD16: 0 | AE16: 0
A17: Barbare | B17: Résistance aux poisons | C17: 6 | D17: 1 | H17: Concoction : Toxicologie | I17: 5 | J17: ='Nom du personnage'!$U$51 -> 0 | K17: 5 | M17: =Concoction!J22 -> 0 | N17: =IF(M17='Bonus Humain'!D18,Compétences!I17-1,VLOOKUP(M17,H17:J74,2,FALSE)) -> #N/A | O17: =N17 -> #N/A | P17: ='Nom du personnage'!$U$51 -> 0 | Q17: Elfe Gris | R17: Lecture et écriture (Elfique) | T17: =+IF(V17=Q17,R17,"N/A") -> N/A | U17: -1 | V17: {='Nom du personnage'!$F$51:$O$51} -> 0 | W17: 0 | X17: 0 | Y17: 0 | Z17: 0 | AA17: 0 | AB17: 0 | AC17: 0 | AD17: 0 | AE17: 0
A18: Barbare | B18: Tir précis | C18: 6 | D18: 1 | H18: Endurance Simple | I18: 3 | J18: ='Nom du personnage'!$U$51 -> 0 | K18: 5 | M18: =IF('Bonus Humain'!H19=0,IF(P18=J18,H18,),'Bonus Humain'!D19) -> Endurance Simple | N18: =IF(M18='Bonus Humain'!D19,Compétences!I18-1,VLOOKUP(M18,H18:J75,2,FALSE)) -> 3 | O18: =VLOOKUP(M18,H18:J75,2,FALSE) -> 3 | P18: ='Nom du personnage'!$U$51 -> 0 | Q18: Elfe Gris | R18: Lecture et écriture (Rakuzan) | T18: =+IF(V18=Q18,R18,"N/A") -> N/A | U18: -1 | V18: {='Nom du personnage'!$F$51:$O$51} -> 0 | W18: 0 | X18: 0 | Y18: 0 | Z18: 0 | AA18: 0 | AB18: 0 | AC18: 0 | AD18: 0 | AE18: 0
A19: Combattant | B19: Bouclier avancé | C19: 3 | D19: 5 | H19: Forge | I19: 3 | J19: ='Nom du personnage'!$U$51 -> 0 | K19: 5 | M19: =IF('Bonus Humain'!H20=0,IF(P19=J19,H19,),'Bonus Humain'!D20) -> Forge | N19: =IF(M19='Bonus Humain'!D20,Compétences!I19-1,VLOOKUP(M19,H19:J76,2,FALSE)) -> 3 | O19: =VLOOKUP(M19,H19:J76,2,FALSE) -> 3 | P19: ='Nom du personnage'!$U$51 -> 0 | Q19: Elfe Gris | R19: Lecture et écriture (Infernal) | T19: =+IF(V19=Q19,R19,"N/A") -> N/A | U19: -1 | V19: {='Nom du personnage'!$F$51:$O$51} -> 0 | W19: 0 | X19: 0 | Y19: 0 | Z19: 0 | AA19: 0 | AB19: 0 | AC19: 0 | AD19: 0 | AE19: 0
A20: Combattant | B20: Bravoure accrue | C20: 6 | D20: 1 | H20: Héraldique | I20: 1 | J20: ='Nom du personnage'!$U$51 -> 0 | K20: 5 | M20: =IF(P20=J20,H20,) -> Héraldique | N20: =IF(M20='Bonus Humain'!D21,Compétences!I20-1,VLOOKUP(M20,H20:J77,2,FALSE)) -> 1 | O20: =VLOOKUP(M20,H20:J77,2,FALSE) -> 1 | P20: ='Nom du personnage'!$U$51 -> 0 | Q20: Elfe Gris | R20: Lecture et écriture (Céleste) | T20: =+IF(V20=Q20,R20,"N/A") -> N/A | U20: -1 | V20: {='Nom du personnage'!$F$51:$O$51} -> 0 | W20: 0 | X20: 0 | Y20: 0 | Z20: 0 | AA20: 0 | AB20: 0 | AC20: 0 | AD20: 0 | AE20: 0
A21: Combattant | B21: Bris d'arme | C21: 6 | D21: 1 | H21: Invocation Guerrière | I21: 3 | J21: ='Nom du personnage'!$U$51 -> 0 | K21: 5 | M21: =IF('Bonus Humain'!H22=0,IF(ISERROR(IF(AND(ISTEXT('Nom du personnage'!F54)=TRUE,'Nom du personnage'!S60>0),H21,))=TRUE,0,IF(AND(ISTEXT('Nom du personnage'!F54)=TRUE,'Nom du personnage'!S60>0),H21,)),'Bonus Humain'!D22) -> #N/A | N21: =IF(M21='Bonus Humain'!D22,Compétences!I21-1,VLOOKUP(M21,H21:J78,2,FALSE)) -> #N/A | O21: =VLOOKUP(M21,H21:J78,2,FALSE) -> #N/A | P21: ='Nom du personnage'!$U$51 -> 0 | Q21: Elfe Gris | R21: Lecture et écriture (Outremonde) | T21: =+IF(V21=Q21,R21,"N/A") -> N/A | U21: -1 | V21: {='Nom du personnage'!$F$51:$O$51} -> 0 | W21: 0 | X21: 0 | Y21: 0 | Z21: 0 | AA21: 0 | AB21: 0 | AC21: 0 | AD21: 0 | AE21: 0
A22: Combattant | B22: Charge | C22: 5 | D22: 5 | H22: Lecture et écriture - Commun | I22: 2 | J22: ='Nom du personnage'!$U$51 -> 0 | K22: 5 | M22: =IF('Bonus Humain'!H23=0,+'Lecture et écriture'!AS4,'Bonus Humain'!D23) -> Lecture et écriture - Commun | N22: =IF(M22='Bonus Humain'!D23,Compétences!I22-1,VLOOKUP(M22,H22:J79,2,FALSE)) -> 2 | O22: =N22 -> 2 | P22: ='Nom du personnage'!$U$51 -> 0 | Q22: Elfe Gris | R22: Lecture et écriture (Vermilangue) | T22: =+IF(V22=Q22,R22,"N/A") -> N/A | U22: -1 | V22: {='Nom du personnage'!$F$51:$O$51} -> 0 | W22: 0 | X22: 0 | Y22: 0 | Z22: 0 | AA22: 0 | AB22: 0 | AC22: 0 | AD22: 0 | AE22: 0
A23: Combattant | B23: Charge accrue | C23: 6 | D23: 5 | H23: Lecture et écriture - Elfique | I23: 2 | J23: ='Nom du personnage'!$U$51 -> 0 | K23: 5 | M23: =IF('Bonus Humain'!H24=0,+'Lecture et écriture'!AS5,'Bonus Humain'!D24) -> Lecture et écriture - Elfique | N23: =IF(M23='Bonus Humain'!D24,Compétences!I23-1,VLOOKUP(M23,H23:J80,2,FALSE)) -> 2 | O23: =N23 -> 2 | P23: ='Nom du personnage'!$U$51 -> 0 | Q23: Elfe Gris | R23: Lecture et écriture (Orque) | T23: =+IF(V23=Q23,R23,"N/A") -> N/A | U23: -1 | V23: {='Nom du personnage'!$F$51:$O$51} -> 0 | W23: 0 | X23: 0 | Y23: 0 | Z23: 0 | AA23: 0 | AB23: 0 | AC23: 0 | AD23: 0 | AE23: 0
A24: Combattant | B24: Contre-charge | C24: 4 | D24: 5 | H24: Lecture et écriture - Rakuzan | I24: 2 | J24: ='Nom du personnage'!$U$51 -> 0 | K24: 5 | M24: =IF('Bonus Humain'!H25=0,+'Lecture et écriture'!AS6,'Bonus Humain'!D25) -> Lecture et écriture - Rakuzan | N24: =IF(M24='Bonus Humain'!D25,Compétences!I24-1,VLOOKUP(M24,H24:J81,2,FALSE)) -> 2 | O24: =N24 -> 2 | P24: ='Nom du personnage'!$U$51 -> 0 | Q24: Elfe Gris | R24: Lecture et écriture (Arcane) | T24: =+IF(V24=Q24,R24,"N/A") -> N/A | U24: -1 | V24: {='Nom du personnage'!$F$51:$O$51} -> 0 | W24: 0 | X24: 0 | Y24: 0 | Z24: 0 | AA24: 0 | AB24: 0 | AC24: 0 | AD24: 0 | AE24: 0
A25: Combattant | B25: Coup meurtrier | C25: 5 | D25: 1 | H25: Lecture et écriture - Infernal | I25: 2 | J25: ='Nom du personnage'!$U$51 -> 0 | K25: 5 | M25: =IF('Bonus Humain'!H26=0,+'Lecture et écriture'!AS7,'Bonus Humain'!D26) -> Lecture et écriture - Infernal | N25: =IF(M25='Bonus Humain'!D26,Compétences!I25-1,VLOOKUP(M25,H25:J82,2,FALSE)) -> 2 | O25: =N25 -> 2 | P25: ='Nom du personnage'!$U$51 -> 0 | Q25: Elfe Gris | R25: Lecture et écriture (Arborique) | T25: =+IF(V25=Q25,R25,"N/A") -> N/A | U25: -1 | V25: {='Nom du personnage'!$F$51:$O$51} -> 0 | W25: 0 | X25: 0 | Y25: 0 | Z25: 0 | AA25: 0 | AB25: 0 | AC25: 0 | AD25: 0 | AE25: 0
A26: Combattant | B26: Coup puissant | C26: 5 | D26: 5 | H26: Lecture et écriture - Céleste | I26: 2 | J26: ='Nom du personnage'!$U$51 -> 0 | K26: 5 | M26: =IF('Bonus Humain'!H27=0,+'Lecture et écriture'!AS8,'Bonus Humain'!D27) -> Lecture et écriture - Céleste | N26: =IF(M26='Bonus Humain'!D27,Compétences!I26-1,VLOOKUP(M26,H26:J83,2,FALSE)) -> 2 | O26: =N26 -> 2 | P26: ='Nom du personnage'!$U$51 -> 0 | Q26: Elfe Gris | R26: Lecture et écriture (Runique) | T26: =+IF(V26=Q26,R26,"N/A") -> N/A | U26: -1 | V26: {='Nom du personnage'!$F$51:$O$51} -> 0 | W26: 0 | X26: 0 | Y26: 0 | Z26: 0 | AA26: 0 | AB26: 0 | AC26: 0 | AD26: 0 | AE26: 0
A27: Combattant | B27: Désarmement | C27: 6 | D27: 5 | H27: Lecture et écriture - Outremonde | I27: 2 | J27: ='Nom du personnage'!$U$51 -> 0 | K27: 5 | M27: =IF('Bonus Humain'!H28=0,+'Lecture et écriture'!AS9,'Bonus Humain'!D28) -> Lecture et écriture - Outremonde | N27: =IF(M27='Bonus Humain'!D28,Compétences!I27-1,VLOOKUP(M27,H27:J84,2,FALSE)) -> 2 | O27: =N27 -> 2 | P27: ='Nom du personnage'!$U$51 -> 0 | Q27: Elfe Gris | R27: Lecture et écriture (Sylvestre) | T27: =+IF(V27=Q27,R27,"N/A") -> N/A | U27: -1 | V27: {='Nom du personnage'!$F$51:$O$51} -> 0 | W27: 0 | X27: 0 | Y27: 0 | Z27: 0 | AA27: 0 | AB27: 0 | AC27: 0 | AD27: 0 | AE27: 0
A28: Combattant | B28: Endurance guerrière | C28: 3 | D28: 5 | H28: Lecture et écriture - Vermilangue | I28: 2 | J28: ='Nom du personnage'!$U$51 -> 0 | K28: 5 | M28: =IF('Bonus Humain'!H29=0,+'Lecture et écriture'!AS10,'Bonus Humain'!D29) -> Lecture et écriture - Vermilangue | N28: =IF(M28='Bonus Humain'!D29,Compétences!I28-1,VLOOKUP(M28,H28:J85,2,FALSE)) -> 2 | O28: =N28 -> 2 | P28: ='Nom du personnage'!$U$51 -> 0 | Q28: Elfe Gris | R28: Haute magie | T28: =+IF(V28=Q28,R28,"N/A") -> N/A | U28: -1 | V28: {='Nom du personnage'!$F$51:$O$51} -> 0 | W28: 0 | X28: 0 | Y28: 0 | Z28: 0 | AA28: 0 | AB28: 0 | AC28: 0 | AD28: 0 | AE28: 0
A29: Combattant | B29: Force brute | C29: 7 | D29: 5 | H29: Lecture et écriture - Orque | I29: 2 | J29: ='Nom du personnage'!$U$51 -> 0 | K29: 5 | M29: =IF('Bonus Humain'!H30=0,+'Lecture et écriture'!AS11,'Bonus Humain'!D30) -> Lecture et écriture - Orque | N29: =IF(M29='Bonus Humain'!D30,Compétences!I29-1,VLOOKUP(M29,H29:J86,2,FALSE)) -> 2 | O29: =N29 -> 2 | P29: ='Nom du personnage'!$U$51 -> 0 | Q29: Elfe Lunaire | R29: Résistance magique | T29: =+IF(V29=Q29,R29,"N/A") -> N/A | U29: -1 | V29: {='Nom du personnage'!$F$51:$O$51} -> 0 | W29: 0 | X29: 0 | Y29: 0 | Z29: 0 | AA29: 0 | AB29: 0 | AC29: 0 | AD29: 0 | AE29: 0
A30: Combattant | B30: Maître abidextre | C30: 2 | D30: 5 | H30: Lecture et écriture - Arcane | I30: 2 | J30: ='Nom du personnage'!$U$51 -> 0 | K30: 5 | M30: =IF('Bonus Humain'!H31=0,+'Lecture et écriture'!AS12,'Bonus Humain'!D31) -> Lecture et écriture - Arcane | N30: =IF(M30='Bonus Humain'!D31,Compétences!I30-1,VLOOKUP(M30,H30:J87,2,FALSE)) -> 2 | O30: =N30 -> 2 | P30: ='Nom du personnage'!$U$51 -> 0 | Q30: Elfe Lunaire | R30: Archerie | T30: =+IF(V30=Q30,R30,"N/A") -> N/A | U30: -1 | V30: {='Nom du personnage'!$F$51:$O$51} -> 0 | W30: 0 | X30: 0 | Y30: 0 | Z30: 0 | AA30: 0 | AB30: 0 | AC30: 0 | AD30: 0 | AE30: 0
A31: Combattant | B31: Port d'armure spécialisée | C31: 6 | D31: 5 | H31: Lecture et écriture - Arborique | I31: 2 | J31: ='Nom du personnage'!$U$51 -> 0 | K31: 5 | M31: =IF('Bonus Humain'!H32=0,+'Lecture et écriture'!AS13,'Bonus Humain'!D32) -> Lecture et écriture - Arborique | N31: =IF(M31='Bonus Humain'!D32,Compétences!I31-1,VLOOKUP(M31,H31:J88,2,FALSE)) -> 2 | O31: =N31 -> 2 | P31: ='Nom du personnage'!$U$51 -> 0 | Q31: Elfe Noir | R31: Torture | T31: =+IF(V31=Q31,R31,"N/A") -> N/A | U31: -1 | V31: {='Nom du personnage'!$F$51:$O$51} -> 0 | W31: 0 | X31: 0 | Y31: 0 | Z31: 0 | AA31: 0 | AB31: 0 | AC31: 0 | AD31: 0 | AE31: 0
